<?xml version='1.0'?>

<robot name="my_robot" xmlns:xacro="http://www.ros.org/wiki/xacro">

  <xacro:include filename="$(find my_robot)/urdf/my_robot.gazebo" />

  <link name="robot_footprint"></link>

  <joint name="robot_footprint_joint" type="fixed">
    <origin xyz="0 0 0" rpy="0 0 0" />
    <parent link="robot_footprint"/>
    <child link="chassis" />
  </joint>

  <link name='chassis'>
    <pose>0 0 0.1 0 0 0</pose>

    <inertial>
      <mass value="15.0"/>
      <origin xyz="0.0 0 0" rpy=" 0 0 0"/>
      <inertia
              ixx="0.1" ixy="0" ixz="0"
              iyy="0.1" iyz="0"
              izz="0.1"
      />
    </inertial>

    <collision name='collision'>
      <origin xyz="0 0 0" rpy=" 0 0 0"/>
      <geometry>
        <box size=".4 .2 .1"/>
      </geometry>
    </collision>

    <visual name='chassis_visual'>
      <origin xyz="0 0 0" rpy=" 0 0 0"/>
      <geometry>
        <box size=".4 .2 .1"/>
      </geometry>
    </visual>

    <collision name='back_caster_collision'>
      <origin xyz="-0.15 0 -0.05" rpy=" 0 0 0"/>
      <geometry>
        <sphere radius="0.0499"/>
      </geometry>
    </collision>

    <visual name='back_caster_visual'>
      <origin xyz="-0.15 0 -0.05" rpy=" 0 0 0"/>
      <geometry>
        <sphere radius="0.05"/>
      </geometry>
    </visual>

    <collision name='front_caster_collision'>
      <origin xyz="0.15 0 -0.05" rpy=" 0 0 0"/>
      <geometry>
        <sphere radius="0.0499"/>
      </geometry>
    </collision>

    <visual name='front_caster_visual'>
      <origin xyz="0.15 0 -0.05" rpy=" 0 0 0"/>
      <geometry>
        <sphere radius="0.05"/>
      </geometry>
    </visual>

  </link>

  <!-- Add two wheels -->

  <link name="left_wheel">
    <inertial>
      <origin xyz="0 0 0" rpy="0 1.5707 1.5707"/>
      <mass value="5"/>
      <inertia
              ixx="0.1" ixy="0" ixz="0"
              iyy="0.1" iyz="0" izz="0.1"
      />
    </inertial>

    <collision>
      <origin xyz="0 0 0" rpy="0 1.5707 1.5707"/>
      <geometry>
        <cylinder radius="0.1" length="0.05"/>
      </geometry>
    </collision>

    <visual>
      <origin xyz="0 0 0" rpy="0 1.5707 1.5707"/>
      <geometry>
        <cylinder radius="0.1" length="0.05"/>
      </geometry>
    </visual>

  </link>

  <link name="right_wheel">
    <inertial>
      <origin xyz="0 0 0" rpy="0 1.5707 1.5707"/>
      <mass value="5"/>
      <inertia
              ixx="0.1" ixy="0" ixz="0"
              iyy="0.1" iyz="0" izz="0.1"
      />
    </inertial>

    <collision>
      <origin xyz="0 0 0" rpy="0 1.5707 1.5707"/>
      <geometry>
        <cylinder radius="0.1" length="0.05"/>
      </geometry>
    </collision>

    <visual>
      <origin xyz="0 0 0" rpy="0 1.5707 1.5707"/>
      <geometry>
        <cylinder radius="0.1" length="0.05"/>
      </geometry>
    </visual>
  </link>

  <joint name="left_wheel_hinge" type="continuous">
    <origin xyz="0 0.125 0" rpy="0 0 0"/>
    <child link="left_wheel"/>
    <parent link="chassis"/>
    <axis xyz="0 1 0" rpy="0 0 0"/>
    <limit effort="10000" velocity="1000"/>
    <dynamics damping="1.0" friction="1.0"/>
  </joint>

  <joint name="right_wheel_hinge" type="continuous">
    <origin xyz="0 -0.125 0" rpy="0 0 0"/>
    <child link="right_wheel"/>
    <parent link="chassis"/>
    <axis xyz="0 1 0" rpy="0 0 0"/>
    <limit effort="10000" velocity="1000"/>
    <dynamics damping="1.0" friction="1.0"/>
  </joint>

  <!-- Add camera -->

  <link name="camera">
    <origin xyz="0 0 0" rpy="0 0 0" />

    <inertial>
      <mass value="0.1"/>
      <inertia
              ixx="1e-6" ixy="0" ixz="0"
              iyy="1e-6" iyz="0" izz="1e-6"
      />
    </inertial>

    <collision>
      <geometry>
        <box size="0.05 0.05 0.05"/>
      </geometry>
    </collision>

    <visual>
      <geometry>
        <box size="0.05 0.05 0.05"/>
      </geometry>
    </visual>
  </link>

  <joint name="camera_joint" type="fixed">
    <axis xyz="0 1 0"/>
    <origin xyz="0.2 0 0" rpy="0 0 0" />
    <parent link="chassis"/>
    <child link="camera" />
  </joint>

  <!-- Add Lidar -->

  <link name="hokuyo">
    <origin xyz="0 0 0" rpy="0 0 0" />

    <inertial>
      <mass value="1e-5"/>
      <inertia
              ixx="1e-6" ixy="0" ixz="0"
              iyy="1e-6" iyz="0" izz="1e-6"
      />
    </inertial>

    <collision>
      <geometry>
        <box size=".1 .1 .1"/>
      </geometry>
    </collision>

    <visual>
      <geometry>
        <mesh filename="package://my_robot/meshes/hokuyo.dae"/>
      </geometry>
    </visual>
  </link>

  <joint name="hokuyo_joint" type="fixed">
    <axis xyz="0 1 0"/>
    <origin xyz="0.15 0 0.1" rpy="0 0 0" />
    <parent link="chassis"/>
    <child link="hokuyo" />
  </joint>

  <!-- Color the components -->

  <gazebo reference="chassis">
    <material>Gazebo/Orange</material>
  </gazebo>

  <gazebo reference="left_wheel">
    <material>Gazebo/Green</material>
  </gazebo>

  <gazebo reference="right_wheel">
    <material>Gazebo/Green</material>
  </gazebo>

  <gazebo reference="camera">
    <material>Gazebo/Red</material>
  </gazebo>

  </robot>
