<?xml version="1.0" encoding="UTF-8"?>

<robot name="my_robot" xmlns:xacro="https://www.ros.org/wiki/xacro" >
<xacro:include filename="$(find my_robot)/urdf/my_robot.gazebo" />

    <gazebo reference="left_wheel">
        <material>Gazebo/Black</material>
    </gazebo>
    <gazebo reference="right_wheel">
        <material>Gazebo/Black</material>
    </gazebo>
    <gazebo reference="chassis">
        <material>Gazebo/Yellow</material>
    </gazebo>
    <gazebo reference="camera">
        <material>Gazebo/Grey</material>
    </gazebo>

        <link name="robot_footprint"></link>
        <joint name="robot_footprint" type="fixed">
            <origin xyz="0 0 0" rpy="0 0 0" />
            <parent link="robot_footprint" />
            <child link="chassis" />
        </joint>

        <link name="chassis">
            <pose>0 0 0.1 0 0 0</pose>
            <inertial>
                <mass value="15.0"/>
                <origin xyz="0.0 0 0" rpy=" 0 0 0"/>
                <inertia
                    ixx="0.1" ixy="0" ixz="0"
                    iyy="0.1" iyz="0"
                    izz="0.1"
                />
              </inertial>
          
              <collision name='collision'>
                <origin xyz="0 0 0" rpy=" 0 0 0"/> 
                <geometry>
                  <box size=".4 .2 .1"/>
                </geometry>
              </collision>
          
              <visual name='chassis_visual'>
                <origin xyz="0 0 0" rpy=" 0 0 0"/>
                <geometry>
                  <box size=".4 .2 .1"/>
                </geometry>
              </visual>
          
          
              <collision name='back_caster_collision'>
                <origin xyz="-0.15 0 -0.05" rpy=" 0 0 0"/>
                <geometry>
                  <sphere radius="0.0499"/>
                </geometry>
              </collision>
          
              <visual name='back_caster_visual'>
                <origin xyz="-0.15 0 -0.05" rpy=" 0 0 0"/>
                <geometry>
                  <sphere radius="0.05"/>
                </geometry>
              </visual>
          
              <collision name='front_caster_collision'>
                <origin xyz="0.15 0 -0.05" rpy=" 0 0 0"/>
                <geometry>
                  <sphere radius="0.0499"/>
                </geometry>
              </collision>
          
              <visual name='front_caster_visual'>
                <origin xyz="0.15 0 -0.05" rpy=" 0 0 0"/>
                <geometry>
                  <sphere radius="0.05"/>
                </geometry>
              </visual>
        </link>
        <joint type="continuous" name="left_wheel_hinge" >
            <origin xyz="0 0.15 0" rpy="0 0 0" />
            <child link="left_wheel" />
            <parent link="chassis" />
            <axis xyz="0 1 0" rpy="0 0 0" />
            <limit effort="10000" velocity="1000" />
            <dynamics damping="1.0" friction="1.0" />
        </joint>
        <link name="left_wheel">
            <visual name="left_wheel_visual">
                <geometry>
                    <cylinder radius='0.1' length='0.05'></cylinder>
                </geometry>
                <origin xyz="0 0 0" rpy="0 1.5708 1.5708"/>
            </visual>
            <collision name="left_wheel_collision">
                <geometry>
                    <cylinder radius='0.1' length='0.05'></cylinder>
                </geometry>
                <origin xyz="0 0 0" rpy="0 1.5708 1.5708"/>
            </collision>
            <inertial>
                <mass value="5"/>
                <origin xyz="0 0 0" rpy="0 1.5708 1.5708" />
                <inertia
                ixx="0.1" ixy="0" ixz="0"
                iyy="0.1" iyz="0"
                izz="0.1"
                />
            </inertial>
        </link>

        

        <link name="right_wheel">
            <visual name="right_wheel_visual">
                <geometry>
                    <cylinder radius='0.1' length='0.05'></cylinder>
                </geometry>
                <origin xyz="0 0 0" rpy="0 1.5708 1.5708"/>
            </visual>
            <collision name="right_wheel_collision">
                <geometry>
                    <cylinder radius='0.1' length='0.05'></cylinder>
                </geometry>
                <origin xyz="0 0 0" rpy="0 1.5708 1.5708"/>
            </collision>
            <inertial>
                <mass value="5"/>
                <origin xyz="0 0 0" rpy="0 1.5708 1.5708" />
                <inertia
                ixx="0.1" ixy="0" ixz="0"
                iyy="0.1" iyz="0"
                izz="0.1"
                />
            </inertial>
        </link>
        
        <joint type="continuous" name="right_wheel_hinge" >
            <origin xyz="0 -0.15 0" rpy="0 0 0" />
            <child link="right_wheel" />
            <parent link="chassis" />
            <axis xyz="0 1 0" rpy="0 0 0" />
            <limit effort="10000" velocity="1000" />
            <dynamics damping="1.0" friction="1.0" />
        </joint>

        <link name="camera">
            <visual name="camera_visual">
                <geometry>
                    <box size="0.05 0.05 0.05"/>
                </geometry>
                <origin xyz="0 0 0" rpy="0 0 0" />
            </visual>
            <collision name="camera_collision">
                <geometry>
                    <box size="0.05 0.05 0.05"/>
                </geometry>
                <origin xyz="0 0 0" rpy="0 0 0" />
            </collision>
            <inertial>
                <mass value="0.1"/>
                <origin xyz="0 0 0" rpy="0 0 0" />
                <inertia
                ixx="1e-6" ixy="0" ixz="0"
                iyy="1e-6" iyz="0"
                izz="1e-6"
                /> 
            </inertial>
        </link>

        <joint type="fixed" name="camera_joint">
            <origin xyz=" 0.2 0 0" rpy="0 0 0" />
            <child link="camera"/>
            <parent link="chassis" />
            <axis xyz=" 0 1 0 " rpy="0 0 0" />
        </joint>

        <link name="hokuyo_front">
            <visual name="hokuyo_visual_front">
                <geometry>
                    <mesh filename="package://my_robot/meshes/hokuyo.dae" />
                </geometry>
                <origin xyz="0 0 0" rpy="0 0 0" />
            </visual>
            <collision name="camera_collision">
                <geometry>
                    <box size="0.1 0.1 0.1"/>
                </geometry>
                <origin xyz="0 0 0" rpy="0 0 0" />
            </collision>
            <inertial>
                <mass value="1e-5"/>
                <origin xyz="0 0 0" rpy="0 0 0" />
                <inertia
                ixx="1e-6" ixy="0" ixz="0"
                iyy="1e-6" iyz="0"
                izz="1e-6"
                /> 
            </inertial>
        </link>

        <joint type="fixed" name="hokuyo_joint_front">
            <origin xyz="0.15 0 0.1" rpy="0 0 0" />
            <parent link="chassis" />
            <child link="hokuyo_front" />
            <axis xyz="0 1 0" rpy="0 0 0" />
        </joint>

         <link name="hokuyo_back">
            <visual name="hokuyo_visual_back">
                <geometry>
                    <mesh filename="package://my_robot/meshes/hokuyo.dae" />
                </geometry>
                <origin xyz="0 0 0" rpy="0 0 0" />
            </visual>
            <collision name="camera_collision">
                <geometry>
                    <box size="0.1 0.1 0.1"/>
                </geometry>
                <origin xyz="0 0 0" rpy="0 0 0" />
            </collision>
            <inertial>
                <mass value="1e-5"/>
                <origin xyz="0 0 0" rpy="0 0 0" />
                <inertia
                ixx="1e-6" ixy="0" ixz="0"
                iyy="1e-6" iyz="0"
                izz="1e-6"
                /> 
            </inertial>
        </link>

        <joint type="fixed" name="hokuyo_joint_back">
            <origin xyz="-0.15 0 0.1" rpy="0 0 0" />
            <parent link="chassis" />
            <child link="hokuyo_back" />
            <axis xyz="0 1 0" rpy="0 0 0" />
        </joint>



</robot>