<?xml version="1.0" encoding="UTF-8"?>
<robot name="vivaRob" xmlns:xacro="http://www.ros.org/wiki/xacro">
    <xacro:include filename="$(find my_robot)/urdf/my_robot.gazebo" />

    <!-- define all the parameters for the robot -->
    <xacro:property name="bodylen" value="0.5" />
    <xacro:property name="width" value="0.25" />
    <xacro:property name="mass_chassis" value="15.0" />
    <xacro:property name="wheel_radius" value="0.1" />
    <xacro:property name="wheel_width" value="0.05" />

    <!-- color property of the robot -->
    <material name="dark_grey"><color rgba="0.2 0.2 0.2 1.0"></color></material>
    <material name="light_grey"><color rgba="0.4 0.4 0.4 1.0"></color></material>
    <material name="yellow"><color rgba="0.8 0.8 0.0 1.0"></color></material>
    <material name="black"><color rgba="0.15 0.15 0.15 1.0"></color></material>
    <gazebo reference="front_left_wheel_link">
        <material>Gazebo/Black</material>
    </gazebo>
    <gazebo reference="front_right_wheel_link">
        <material>Gazebo/Black</material>
    </gazebo>
    <gazebo reference="rear_left_wheel_link">
        <material>Gazebo/Black</material>
    </gazebo>
    <gazebo reference="rear_right_wheel_link">
        <material>Gazebo/Black</material>
    </gazebo>
    <gazebo reference="chassis">
        <material>Gazebo/Yellow</material>
    </gazebo>
    <gazebo reference="camera">
        <material>Gazebo/Grey</material>
    </gazebo>

    <!-- define macros for the robot -->
    <xacro:property  name="origin0">
        <origin xyz=" 0 0 0 " rpy=" 0 0 0"/>
    </xacro:property>
    <!-- box geometry macro -->
    <xacro:property name="box_geometry">
        <geometry>
            <box size="${bodylen} ${width} 0.05" />
        </geometry>
    </xacro:property>

    <link name="base_link"></link>
    <joint name="base_link_joint" type="fixed">
        <parent link="base_link" />
        <origin xyz="0 0 0" rpy="0 0 0 " />
        <child link="chassis" />
    </joint>
   <!-- robot chassis link -->
    <link name="chassis">
        <pose>0 0 0.5 0 0 0</pose>
        <visual name="chassis_visual">
            <xacro:insert_block name="origin0" />
            <xacro:insert_block name="box_geometry"  />
            <material name="yellow" />
        </visual>
        <collision name="chassis_collision">
            <xacro:insert_block name="origin0" />
            <xacro:insert_block name="box_geometry"  />
        </collision>
        <inertial>
            <mass value="${mass_chassis}" />
            <xacro:insert_block name="origin0" />
            <inertia
                ixx="0.2" ixy="0" ixz="0"
                iyy="0.2" iyz="0"
                izz="0.1"
                />
        </inertial>
    </link>

    <!-- links and joints xacro macro for the robot -->
    <xacro:macro name="wheel" params="prefix *joint_pose">
        <link name="${prefix}_wheel_link">
            <visual>
                <material name="black"></material>
                <geometry>
                    <cylinder radius='${wheel_radius}' length='${wheel_width}'/>
                </geometry>
                <origin xyz="0 0 0" rpy="0 1.5708 1.5708"/>
            </visual>
            <collision>
                <geometry>
                    <cylinder radius='${wheel_radius}' length='${wheel_width}'/>
                </geometry>
                <origin xyz="0 0 0" rpy="0 1.5708 1.5708"/>
            </collision>
            <inertial>
                <mass value="5"/>
                <origin xyz="0 0 0" rpy="0 1.5708 1.5708" />
                <inertia
                ixx="0.1" ixy="0" ixz="0"
                iyy="0.1" iyz="0"
                izz="0.1"
                />
            </inertial>
        </link>

        <joint type="continuous" name="${prefix}_wheel_hinge" >
            <!-- <origin xyz="0 -0.15 0" rpy="0 0 0" /> -->
            <xacro:insert_block name="joint_pose" />
            <child link="${prefix}_wheel_link" />
            <parent link="chassis" />
            <axis xyz="0 1 0" rpy="0 0 0" />
            <limit effort="10000" velocity="1000" />
            <dynamics damping="1.0" friction="1.0" />
        </joint>
    </xacro:macro>

    <!-- insert four wheels -->
    <xacro:wheel prefix="left_front">
       <origin xyz="0.2 -0.18 0" rpy="0 0 0" />
    </xacro:wheel>
    <xacro:wheel prefix="right_front">
       <origin xyz="0.2 0.18 0" rpy="0 0 0" />
    </xacro:wheel>
    <xacro:wheel prefix="left_back">
       <origin xyz="-0.2 -0.18 0" rpy="0 0 0" />
    </xacro:wheel>
    <xacro:wheel prefix="right_back">
       <origin xyz="-0.2 0.18 0" rpy="0 0 0" />
    </xacro:wheel>


    <link name="camera">
        <visual name="camera_visual">
            <geometry>
                <box size="0.05 0.05 0.05"/>
            </geometry>
            <origin xyz="0 0 0" rpy="0 0 0" />
            <material name="light_grey" />
        </visual>
        <collision name="camera_collision">
            <geometry>
                <box size="0.05 0.05 0.05"/>
            </geometry>
            <origin xyz="0 0 0" rpy="0 0 0" />
        </collision>
        <inertial>
            <mass value="0.1"/>
            <origin xyz="0 0 0" rpy="0 0 0" />
            <inertia
            ixx="1e-6" ixy="0" ixz="0"
            iyy="1e-6" iyz="0"
            izz="1e-6"
            /> 
        </inertial>
    </link>

    <joint type="fixed" name="camera_joint">
        <origin xyz=" 0.28 0 0" rpy="0 0 0" />
        <child link="camera"/>
        <parent link="chassis" />
        <axis xyz=" 0 1 0 " rpy="0 0 0" />
    </joint>

    <link name="hokuyo">
        <visual name="hokuyo_visual">
            <geometry>
                <mesh filename="package://my_robot/meshes/hokuyo.dae" />
            </geometry>
            <origin xyz="0 0 0" rpy="0 0 0" />
        </visual>
        <collision name="camera_collision">
            <geometry>
                <box size="0.1 0.1 0.1"/>
            </geometry>
            <origin xyz="0 0 0" rpy="0 0 0" />
        </collision>
        <inertial>
            <mass value="1e-5"/>
            <origin xyz="0 0 0" rpy="0 0 0" />
            <inertia
            ixx="1e-6" ixy="0" ixz="0"
            iyy="1e-6" iyz="0"
            izz="1e-6"
            /> 
        </inertial>
    </link>

    <joint type="fixed" name="hokuyo_joint">
        <origin xyz="0.2 0 0.05" rpy="0 0 0" />
        <parent link="chassis" />
        <child link="hokuyo" />
        <axis xyz="0 1 0" rpy="0 0 0" />
    </joint>

</robot>